
2021-05-02 16:54:33,017 INFO: errors [in /Users/felixeigenbrodt/Documents/webprojects/classroom/01_fyyur/starter_code/app.py:553]
2021-05-02 16:54:47,763 INFO: errors [in /Users/felixeigenbrodt/Documents/webprojects/classroom/01_fyyur/starter_code/app.py:553]
2021-05-02 16:57:14,221 INFO: errors [in /Users/felixeigenbrodt/Documents/webprojects/classroom/01_fyyur/starter_code/app.py:554]
2021-05-02 16:57:39,290 INFO: errors [in /Users/felixeigenbrodt/Documents/webprojects/classroom/01_fyyur/starter_code/app.py:554]
2021-05-02 17:01:23,690 INFO: errors [in /Users/felixeigenbrodt/Documents/webprojects/classroom/01_fyyur/starter_code/app.py:569]
2021-05-02 17:01:27,573 INFO: errors [in /Users/felixeigenbrodt/Documents/webprojects/classroom/01_fyyur/starter_code/app.py:569]
2021-05-02 17:01:41,524 INFO: errors [in /Users/felixeigenbrodt/Documents/webprojects/classroom/01_fyyur/starter_code/app.py:569]
2021-05-02 17:02:48,878 INFO: errors [in /Users/felixeigenbrodt/Documents/webprojects/classroom/01_fyyur/starter_code/app.py:569]
2021-05-02 17:04:25,855 INFO: errors [in /Users/felixeigenbrodt/Documents/webprojects/classroom/01_fyyur/starter_code/app.py:569]
2021-05-02 17:04:28,548 INFO: errors [in /Users/felixeigenbrodt/Documents/webprojects/classroom/01_fyyur/starter_code/app.py:569]
2021-05-02 17:04:34,047 INFO: errors [in /Users/felixeigenbrodt/Documents/webprojects/classroom/01_fyyur/starter_code/app.py:569]
2021-05-02 17:05:23,418 INFO: errors [in /Users/felixeigenbrodt/Documents/webprojects/classroom/01_fyyur/starter_code/app.py:569]
2021-05-02 17:05:29,453 INFO: errors [in /Users/felixeigenbrodt/Documents/webprojects/classroom/01_fyyur/starter_code/app.py:569]
2021-05-02 17:45:21,878 INFO: errors [in /Users/felixeigenbrodt/Documents/webprojects/classroom/01_fyyur/starter_code/app.py:808]
2021-05-02 17:45:31,063 INFO: errors [in /Users/felixeigenbrodt/Documents/webprojects/classroom/01_fyyur/starter_code/app.py:808]
2021-05-02 17:56:31,839 INFO: errors [in /Users/felixeigenbrodt/Documents/webprojects/classroom/01_fyyur/starter_code/app.py:809]
2021-05-02 17:56:36,894 INFO: errors [in /Users/felixeigenbrodt/Documents/webprojects/classroom/01_fyyur/starter_code/app.py:809]
2021-05-02 17:56:51,450 INFO: errors [in /Users/felixeigenbrodt/Documents/webprojects/classroom/01_fyyur/starter_code/app.py:809]
2021-05-14 14:45:23,527 INFO: errors [in /Users/felixeigenbrodt/Documents/webprojects/classroom/01_fyyur/fyyur/app.py:488]
2021-05-14 14:45:32,631 ERROR: Exception on /venues/create [POST] [in /Library/Frameworks/Python.framework/Versions/3.9/lib/python3.9/site-packages/flask/app.py:1890]
Traceback (most recent call last):
  File "/Library/Frameworks/Python.framework/Versions/3.9/lib/python3.9/site-packages/flask/app.py", line 2446, in wsgi_app
    response = self.full_dispatch_request()
  File "/Library/Frameworks/Python.framework/Versions/3.9/lib/python3.9/site-packages/flask/app.py", line 1951, in full_dispatch_request
    rv = self.handle_user_exception(e)
  File "/Library/Frameworks/Python.framework/Versions/3.9/lib/python3.9/site-packages/flask/app.py", line 1820, in handle_user_exception
    reraise(exc_type, exc_value, tb)
  File "/Library/Frameworks/Python.framework/Versions/3.9/lib/python3.9/site-packages/flask/_compat.py", line 39, in reraise
    raise value
  File "/Library/Frameworks/Python.framework/Versions/3.9/lib/python3.9/site-packages/flask/app.py", line 1949, in full_dispatch_request
    rv = self.dispatch_request()
  File "/Library/Frameworks/Python.framework/Versions/3.9/lib/python3.9/site-packages/flask/app.py", line 1935, in dispatch_request
    return self.view_functions[rule.endpoint](**req.view_args)
  File "/Users/felixeigenbrodt/Documents/webprojects/classroom/01_fyyur/fyyur/app.py", line 170, in create_venue_submission
    form = VenueForm(request.form)
  File "/Library/Frameworks/Python.framework/Versions/3.9/lib/python3.9/site-packages/wtforms/form.py", line 212, in __call__
    return type.__call__(cls, *args, **kwargs)
  File "/Library/Frameworks/Python.framework/Versions/3.9/lib/python3.9/site-packages/flask_wtf/form.py", line 88, in __init__
    super(FlaskForm, self).__init__(formdata=formdata, **kwargs)
  File "/Library/Frameworks/Python.framework/Versions/3.9/lib/python3.9/site-packages/wtforms/form.py", line 278, in __init__
    self.process(formdata, obj, data=data, **kwargs)
  File "/Library/Frameworks/Python.framework/Versions/3.9/lib/python3.9/site-packages/wtforms/form.py", line 132, in process
    field.process(formdata)
  File "/Library/Frameworks/Python.framework/Versions/3.9/lib/python3.9/site-packages/wtforms/csrf/core.py", line 43, in process
    self.current_token = self.csrf_impl.generate_csrf_token(self)
  File "/Library/Frameworks/Python.framework/Versions/3.9/lib/python3.9/site-packages/flask_wtf/csrf.py", line 132, in generate_csrf_token
    return generate_csrf(
  File "/Library/Frameworks/Python.framework/Versions/3.9/lib/python3.9/site-packages/flask_wtf/csrf.py", line 33, in generate_csrf
    secret_key = _get_config(
  File "/Library/Frameworks/Python.framework/Versions/3.9/lib/python3.9/site-packages/flask_wtf/csrf.py", line 121, in _get_config
    raise KeyError(message)
KeyError: 'A secret key is required to use CSRF.'
2021-05-14 14:45:37,622 ERROR: Exception on /venues [GET] [in /Library/Frameworks/Python.framework/Versions/3.9/lib/python3.9/site-packages/flask/app.py:1890]
Traceback (most recent call last):
  File "/Library/Frameworks/Python.framework/Versions/3.9/lib/python3.9/site-packages/sqlalchemy/util/_collections.py", line 1010, in __call__
    return self.registry[key]
KeyError: <greenlet.greenlet object at 0x7fddea78cf60 (otid=0x7fddea765b00) current active started main>

During handling of the above exception, another exception occurred:

Traceback (most recent call last):
  File "/Library/Frameworks/Python.framework/Versions/3.9/lib/python3.9/site-packages/flask/app.py", line 2446, in wsgi_app
    response = self.full_dispatch_request()
  File "/Library/Frameworks/Python.framework/Versions/3.9/lib/python3.9/site-packages/flask/app.py", line 1951, in full_dispatch_request
    rv = self.handle_user_exception(e)
  File "/Library/Frameworks/Python.framework/Versions/3.9/lib/python3.9/site-packages/flask/app.py", line 1820, in handle_user_exception
    reraise(exc_type, exc_value, tb)
  File "/Library/Frameworks/Python.framework/Versions/3.9/lib/python3.9/site-packages/flask/_compat.py", line 39, in reraise
    raise value
  File "/Library/Frameworks/Python.framework/Versions/3.9/lib/python3.9/site-packages/flask/app.py", line 1949, in full_dispatch_request
    rv = self.dispatch_request()
  File "/Library/Frameworks/Python.framework/Versions/3.9/lib/python3.9/site-packages/flask/app.py", line 1935, in dispatch_request
    return self.view_functions[rule.endpoint](**req.view_args)
  File "/Users/felixeigenbrodt/Documents/webprojects/classroom/01_fyyur/fyyur/app.py", line 70, in venues
    venues = Venue.query.all()
  File "/Library/Frameworks/Python.framework/Versions/3.9/lib/python3.9/site-packages/flask_sqlalchemy/__init__.py", line 519, in __get__
    return type.query_class(mapper, session=self.sa.session())
  File "/Library/Frameworks/Python.framework/Versions/3.9/lib/python3.9/site-packages/sqlalchemy/orm/scoping.py", line 78, in __call__
    return self.registry()
  File "/Library/Frameworks/Python.framework/Versions/3.9/lib/python3.9/site-packages/sqlalchemy/util/_collections.py", line 1012, in __call__
    return self.registry.setdefault(key, self.createfunc())
  File "/Library/Frameworks/Python.framework/Versions/3.9/lib/python3.9/site-packages/sqlalchemy/orm/session.py", line 3225, in __call__
    return self.class_(**local_kw)
  File "/Library/Frameworks/Python.framework/Versions/3.9/lib/python3.9/site-packages/flask_sqlalchemy/__init__.py", line 137, in __init__
    track_modifications = app.config['SQLALCHEMY_TRACK_MODIFICATIONS']
KeyError: 'SQLALCHEMY_TRACK_MODIFICATIONS'
